{
 "cells": [
  {
   "cell_type": "code",
   "execution_count": 1,
   "metadata": {},
   "outputs": [
    {
     "name": "stderr",
     "output_type": "stream",
     "text": [
      "\n",
      "A module that was compiled using NumPy 1.x cannot be run in\n",
      "NumPy 2.0.1 as it may crash. To support both 1.x and 2.x\n",
      "versions of NumPy, modules must be compiled with NumPy 2.0.\n",
      "Some module may need to rebuild instead e.g. with 'pybind11>=2.12'.\n",
      "\n",
      "If you are a user of the module, the easiest solution will be to\n",
      "downgrade to 'numpy<2' or try to upgrade the affected module.\n",
      "We expect that some modules will need time to support NumPy 2.\n",
      "\n",
      "Traceback (most recent call last):  File \"<frozen runpy>\", line 198, in _run_module_as_main\n",
      "  File \"<frozen runpy>\", line 88, in _run_code\n",
      "  File \"/Users/mhd/anaconda3/lib/python3.11/site-packages/ipykernel_launcher.py\", line 18, in <module>\n",
      "    app.launch_new_instance()\n",
      "  File \"/Users/mhd/anaconda3/lib/python3.11/site-packages/traitlets/config/application.py\", line 1075, in launch_instance\n",
      "    app.start()\n",
      "  File \"/Users/mhd/anaconda3/lib/python3.11/site-packages/ipykernel/kernelapp.py\", line 739, in start\n",
      "    self.io_loop.start()\n",
      "  File \"/Users/mhd/anaconda3/lib/python3.11/site-packages/tornado/platform/asyncio.py\", line 205, in start\n",
      "    self.asyncio_loop.run_forever()\n",
      "  File \"/Users/mhd/anaconda3/lib/python3.11/asyncio/base_events.py\", line 608, in run_forever\n",
      "    self._run_once()\n",
      "  File \"/Users/mhd/anaconda3/lib/python3.11/asyncio/base_events.py\", line 1936, in _run_once\n",
      "    handle._run()\n",
      "  File \"/Users/mhd/anaconda3/lib/python3.11/asyncio/events.py\", line 84, in _run\n",
      "    self._context.run(self._callback, *self._args)\n",
      "  File \"/Users/mhd/anaconda3/lib/python3.11/site-packages/ipykernel/kernelbase.py\", line 545, in dispatch_queue\n",
      "    await self.process_one()\n",
      "  File \"/Users/mhd/anaconda3/lib/python3.11/site-packages/ipykernel/kernelbase.py\", line 534, in process_one\n",
      "    await dispatch(*args)\n",
      "  File \"/Users/mhd/anaconda3/lib/python3.11/site-packages/ipykernel/kernelbase.py\", line 437, in dispatch_shell\n",
      "    await result\n",
      "  File \"/Users/mhd/anaconda3/lib/python3.11/site-packages/ipykernel/ipkernel.py\", line 362, in execute_request\n",
      "    await super().execute_request(stream, ident, parent)\n",
      "  File \"/Users/mhd/anaconda3/lib/python3.11/site-packages/ipykernel/kernelbase.py\", line 778, in execute_request\n",
      "    reply_content = await reply_content\n",
      "  File \"/Users/mhd/anaconda3/lib/python3.11/site-packages/ipykernel/ipkernel.py\", line 449, in do_execute\n",
      "    res = shell.run_cell(\n",
      "  File \"/Users/mhd/anaconda3/lib/python3.11/site-packages/ipykernel/zmqshell.py\", line 549, in run_cell\n",
      "    return super().run_cell(*args, **kwargs)\n",
      "  File \"/Users/mhd/anaconda3/lib/python3.11/site-packages/IPython/core/interactiveshell.py\", line 3048, in run_cell\n",
      "    result = self._run_cell(\n",
      "  File \"/Users/mhd/anaconda3/lib/python3.11/site-packages/IPython/core/interactiveshell.py\", line 3103, in _run_cell\n",
      "    result = runner(coro)\n",
      "  File \"/Users/mhd/anaconda3/lib/python3.11/site-packages/IPython/core/async_helpers.py\", line 129, in _pseudo_sync_runner\n",
      "    coro.send(None)\n",
      "  File \"/Users/mhd/anaconda3/lib/python3.11/site-packages/IPython/core/interactiveshell.py\", line 3308, in run_cell_async\n",
      "    has_raised = await self.run_ast_nodes(code_ast.body, cell_name,\n",
      "  File \"/Users/mhd/anaconda3/lib/python3.11/site-packages/IPython/core/interactiveshell.py\", line 3490, in run_ast_nodes\n",
      "    if await self.run_code(code, result, async_=asy):\n",
      "  File \"/Users/mhd/anaconda3/lib/python3.11/site-packages/IPython/core/interactiveshell.py\", line 3550, in run_code\n",
      "    exec(code_obj, self.user_global_ns, self.user_ns)\n",
      "  File \"/var/folders/s9/5nkmbr990tg499cjlzfn9s600000gn/T/ipykernel_37135/2250472753.py\", line 2, in <module>\n",
      "    from google.cloud import bigquery\n",
      "  File \"/Users/mhd/anaconda3/lib/python3.11/site-packages/google/cloud/bigquery/__init__.py\", line 35, in <module>\n",
      "    from google.cloud.bigquery.client import Client\n",
      "  File \"/Users/mhd/anaconda3/lib/python3.11/site-packages/google/cloud/bigquery/client.py\", line 69, in <module>\n",
      "    from google.cloud.bigquery import _job_helpers\n",
      "  File \"/Users/mhd/anaconda3/lib/python3.11/site-packages/google/cloud/bigquery/_job_helpers.py\", line 47, in <module>\n",
      "    from google.cloud.bigquery import job\n",
      "  File \"/Users/mhd/anaconda3/lib/python3.11/site-packages/google/cloud/bigquery/job/__init__.py\", line 27, in <module>\n",
      "    from google.cloud.bigquery.job.copy_ import CopyJob\n",
      "  File \"/Users/mhd/anaconda3/lib/python3.11/site-packages/google/cloud/bigquery/job/copy_.py\", line 22, in <module>\n",
      "    from google.cloud.bigquery.table import TableReference\n",
      "  File \"/Users/mhd/anaconda3/lib/python3.11/site-packages/google/cloud/bigquery/table.py\", line 28, in <module>\n",
      "    import pandas  # type: ignore\n",
      "  File \"/Users/mhd/anaconda3/lib/python3.11/site-packages/pandas/__init__.py\", line 26, in <module>\n",
      "    from pandas.compat import (\n",
      "  File \"/Users/mhd/anaconda3/lib/python3.11/site-packages/pandas/compat/__init__.py\", line 27, in <module>\n",
      "    from pandas.compat.pyarrow import (\n",
      "  File \"/Users/mhd/anaconda3/lib/python3.11/site-packages/pandas/compat/pyarrow.py\", line 8, in <module>\n",
      "    import pyarrow as pa\n",
      "  File \"/Users/mhd/anaconda3/lib/python3.11/site-packages/pyarrow/__init__.py\", line 65, in <module>\n",
      "    import pyarrow.lib as _lib\n"
     ]
    },
    {
     "ename": "AttributeError",
     "evalue": "_ARRAY_API not found",
     "output_type": "error",
     "traceback": [
      "\u001b[0;31m---------------------------------------------------------------------------\u001b[0m",
      "\u001b[0;31mAttributeError\u001b[0m                            Traceback (most recent call last)",
      "\u001b[0;31mAttributeError\u001b[0m: _ARRAY_API not found"
     ]
    },
    {
     "name": "stderr",
     "output_type": "stream",
     "text": [
      "\n",
      "A module that was compiled using NumPy 1.x cannot be run in\n",
      "NumPy 2.0.1 as it may crash. To support both 1.x and 2.x\n",
      "versions of NumPy, modules must be compiled with NumPy 2.0.\n",
      "Some module may need to rebuild instead e.g. with 'pybind11>=2.12'.\n",
      "\n",
      "If you are a user of the module, the easiest solution will be to\n",
      "downgrade to 'numpy<2' or try to upgrade the affected module.\n",
      "We expect that some modules will need time to support NumPy 2.\n",
      "\n",
      "Traceback (most recent call last):  File \"<frozen runpy>\", line 198, in _run_module_as_main\n",
      "  File \"<frozen runpy>\", line 88, in _run_code\n",
      "  File \"/Users/mhd/anaconda3/lib/python3.11/site-packages/ipykernel_launcher.py\", line 18, in <module>\n",
      "    app.launch_new_instance()\n",
      "  File \"/Users/mhd/anaconda3/lib/python3.11/site-packages/traitlets/config/application.py\", line 1075, in launch_instance\n",
      "    app.start()\n",
      "  File \"/Users/mhd/anaconda3/lib/python3.11/site-packages/ipykernel/kernelapp.py\", line 739, in start\n",
      "    self.io_loop.start()\n",
      "  File \"/Users/mhd/anaconda3/lib/python3.11/site-packages/tornado/platform/asyncio.py\", line 205, in start\n",
      "    self.asyncio_loop.run_forever()\n",
      "  File \"/Users/mhd/anaconda3/lib/python3.11/asyncio/base_events.py\", line 608, in run_forever\n",
      "    self._run_once()\n",
      "  File \"/Users/mhd/anaconda3/lib/python3.11/asyncio/base_events.py\", line 1936, in _run_once\n",
      "    handle._run()\n",
      "  File \"/Users/mhd/anaconda3/lib/python3.11/asyncio/events.py\", line 84, in _run\n",
      "    self._context.run(self._callback, *self._args)\n",
      "  File \"/Users/mhd/anaconda3/lib/python3.11/site-packages/ipykernel/kernelbase.py\", line 545, in dispatch_queue\n",
      "    await self.process_one()\n",
      "  File \"/Users/mhd/anaconda3/lib/python3.11/site-packages/ipykernel/kernelbase.py\", line 534, in process_one\n",
      "    await dispatch(*args)\n",
      "  File \"/Users/mhd/anaconda3/lib/python3.11/site-packages/ipykernel/kernelbase.py\", line 437, in dispatch_shell\n",
      "    await result\n",
      "  File \"/Users/mhd/anaconda3/lib/python3.11/site-packages/ipykernel/ipkernel.py\", line 362, in execute_request\n",
      "    await super().execute_request(stream, ident, parent)\n",
      "  File \"/Users/mhd/anaconda3/lib/python3.11/site-packages/ipykernel/kernelbase.py\", line 778, in execute_request\n",
      "    reply_content = await reply_content\n",
      "  File \"/Users/mhd/anaconda3/lib/python3.11/site-packages/ipykernel/ipkernel.py\", line 449, in do_execute\n",
      "    res = shell.run_cell(\n",
      "  File \"/Users/mhd/anaconda3/lib/python3.11/site-packages/ipykernel/zmqshell.py\", line 549, in run_cell\n",
      "    return super().run_cell(*args, **kwargs)\n",
      "  File \"/Users/mhd/anaconda3/lib/python3.11/site-packages/IPython/core/interactiveshell.py\", line 3048, in run_cell\n",
      "    result = self._run_cell(\n",
      "  File \"/Users/mhd/anaconda3/lib/python3.11/site-packages/IPython/core/interactiveshell.py\", line 3103, in _run_cell\n",
      "    result = runner(coro)\n",
      "  File \"/Users/mhd/anaconda3/lib/python3.11/site-packages/IPython/core/async_helpers.py\", line 129, in _pseudo_sync_runner\n",
      "    coro.send(None)\n",
      "  File \"/Users/mhd/anaconda3/lib/python3.11/site-packages/IPython/core/interactiveshell.py\", line 3308, in run_cell_async\n",
      "    has_raised = await self.run_ast_nodes(code_ast.body, cell_name,\n",
      "  File \"/Users/mhd/anaconda3/lib/python3.11/site-packages/IPython/core/interactiveshell.py\", line 3490, in run_ast_nodes\n",
      "    if await self.run_code(code, result, async_=asy):\n",
      "  File \"/Users/mhd/anaconda3/lib/python3.11/site-packages/IPython/core/interactiveshell.py\", line 3550, in run_code\n",
      "    exec(code_obj, self.user_global_ns, self.user_ns)\n",
      "  File \"/var/folders/s9/5nkmbr990tg499cjlzfn9s600000gn/T/ipykernel_37135/2250472753.py\", line 2, in <module>\n",
      "    from google.cloud import bigquery\n",
      "  File \"/Users/mhd/anaconda3/lib/python3.11/site-packages/google/cloud/bigquery/__init__.py\", line 35, in <module>\n",
      "    from google.cloud.bigquery.client import Client\n",
      "  File \"/Users/mhd/anaconda3/lib/python3.11/site-packages/google/cloud/bigquery/client.py\", line 69, in <module>\n",
      "    from google.cloud.bigquery import _job_helpers\n",
      "  File \"/Users/mhd/anaconda3/lib/python3.11/site-packages/google/cloud/bigquery/_job_helpers.py\", line 47, in <module>\n",
      "    from google.cloud.bigquery import job\n",
      "  File \"/Users/mhd/anaconda3/lib/python3.11/site-packages/google/cloud/bigquery/job/__init__.py\", line 27, in <module>\n",
      "    from google.cloud.bigquery.job.copy_ import CopyJob\n",
      "  File \"/Users/mhd/anaconda3/lib/python3.11/site-packages/google/cloud/bigquery/job/copy_.py\", line 22, in <module>\n",
      "    from google.cloud.bigquery.table import TableReference\n",
      "  File \"/Users/mhd/anaconda3/lib/python3.11/site-packages/google/cloud/bigquery/table.py\", line 28, in <module>\n",
      "    import pandas  # type: ignore\n",
      "  File \"/Users/mhd/anaconda3/lib/python3.11/site-packages/pandas/__init__.py\", line 49, in <module>\n",
      "    from pandas.core.api import (\n",
      "  File \"/Users/mhd/anaconda3/lib/python3.11/site-packages/pandas/core/api.py\", line 9, in <module>\n",
      "    from pandas.core.dtypes.dtypes import (\n",
      "  File \"/Users/mhd/anaconda3/lib/python3.11/site-packages/pandas/core/dtypes/dtypes.py\", line 24, in <module>\n",
      "    from pandas._libs import (\n",
      "  File \"/Users/mhd/anaconda3/lib/python3.11/site-packages/pyarrow/__init__.py\", line 65, in <module>\n",
      "    import pyarrow.lib as _lib\n"
     ]
    },
    {
     "ename": "AttributeError",
     "evalue": "_ARRAY_API not found",
     "output_type": "error",
     "traceback": [
      "\u001b[0;31m---------------------------------------------------------------------------\u001b[0m",
      "\u001b[0;31mAttributeError\u001b[0m                            Traceback (most recent call last)",
      "\u001b[0;31mAttributeError\u001b[0m: _ARRAY_API not found"
     ]
    },
    {
     "name": "stderr",
     "output_type": "stream",
     "text": [
      "\n",
      "A module that was compiled using NumPy 1.x cannot be run in\n",
      "NumPy 2.0.1 as it may crash. To support both 1.x and 2.x\n",
      "versions of NumPy, modules must be compiled with NumPy 2.0.\n",
      "Some module may need to rebuild instead e.g. with 'pybind11>=2.12'.\n",
      "\n",
      "If you are a user of the module, the easiest solution will be to\n",
      "downgrade to 'numpy<2' or try to upgrade the affected module.\n",
      "We expect that some modules will need time to support NumPy 2.\n",
      "\n",
      "Traceback (most recent call last):  File \"<frozen runpy>\", line 198, in _run_module_as_main\n",
      "  File \"<frozen runpy>\", line 88, in _run_code\n",
      "  File \"/Users/mhd/anaconda3/lib/python3.11/site-packages/ipykernel_launcher.py\", line 18, in <module>\n",
      "    app.launch_new_instance()\n",
      "  File \"/Users/mhd/anaconda3/lib/python3.11/site-packages/traitlets/config/application.py\", line 1075, in launch_instance\n",
      "    app.start()\n",
      "  File \"/Users/mhd/anaconda3/lib/python3.11/site-packages/ipykernel/kernelapp.py\", line 739, in start\n",
      "    self.io_loop.start()\n",
      "  File \"/Users/mhd/anaconda3/lib/python3.11/site-packages/tornado/platform/asyncio.py\", line 205, in start\n",
      "    self.asyncio_loop.run_forever()\n",
      "  File \"/Users/mhd/anaconda3/lib/python3.11/asyncio/base_events.py\", line 608, in run_forever\n",
      "    self._run_once()\n",
      "  File \"/Users/mhd/anaconda3/lib/python3.11/asyncio/base_events.py\", line 1936, in _run_once\n",
      "    handle._run()\n",
      "  File \"/Users/mhd/anaconda3/lib/python3.11/asyncio/events.py\", line 84, in _run\n",
      "    self._context.run(self._callback, *self._args)\n",
      "  File \"/Users/mhd/anaconda3/lib/python3.11/site-packages/ipykernel/kernelbase.py\", line 545, in dispatch_queue\n",
      "    await self.process_one()\n",
      "  File \"/Users/mhd/anaconda3/lib/python3.11/site-packages/ipykernel/kernelbase.py\", line 534, in process_one\n",
      "    await dispatch(*args)\n",
      "  File \"/Users/mhd/anaconda3/lib/python3.11/site-packages/ipykernel/kernelbase.py\", line 437, in dispatch_shell\n",
      "    await result\n",
      "  File \"/Users/mhd/anaconda3/lib/python3.11/site-packages/ipykernel/ipkernel.py\", line 362, in execute_request\n",
      "    await super().execute_request(stream, ident, parent)\n",
      "  File \"/Users/mhd/anaconda3/lib/python3.11/site-packages/ipykernel/kernelbase.py\", line 778, in execute_request\n",
      "    reply_content = await reply_content\n",
      "  File \"/Users/mhd/anaconda3/lib/python3.11/site-packages/ipykernel/ipkernel.py\", line 449, in do_execute\n",
      "    res = shell.run_cell(\n",
      "  File \"/Users/mhd/anaconda3/lib/python3.11/site-packages/ipykernel/zmqshell.py\", line 549, in run_cell\n",
      "    return super().run_cell(*args, **kwargs)\n",
      "  File \"/Users/mhd/anaconda3/lib/python3.11/site-packages/IPython/core/interactiveshell.py\", line 3048, in run_cell\n",
      "    result = self._run_cell(\n",
      "  File \"/Users/mhd/anaconda3/lib/python3.11/site-packages/IPython/core/interactiveshell.py\", line 3103, in _run_cell\n",
      "    result = runner(coro)\n",
      "  File \"/Users/mhd/anaconda3/lib/python3.11/site-packages/IPython/core/async_helpers.py\", line 129, in _pseudo_sync_runner\n",
      "    coro.send(None)\n",
      "  File \"/Users/mhd/anaconda3/lib/python3.11/site-packages/IPython/core/interactiveshell.py\", line 3308, in run_cell_async\n",
      "    has_raised = await self.run_ast_nodes(code_ast.body, cell_name,\n",
      "  File \"/Users/mhd/anaconda3/lib/python3.11/site-packages/IPython/core/interactiveshell.py\", line 3490, in run_ast_nodes\n",
      "    if await self.run_code(code, result, async_=asy):\n",
      "  File \"/Users/mhd/anaconda3/lib/python3.11/site-packages/IPython/core/interactiveshell.py\", line 3550, in run_code\n",
      "    exec(code_obj, self.user_global_ns, self.user_ns)\n",
      "  File \"/var/folders/s9/5nkmbr990tg499cjlzfn9s600000gn/T/ipykernel_37135/2250472753.py\", line 2, in <module>\n",
      "    from google.cloud import bigquery\n",
      "  File \"/Users/mhd/anaconda3/lib/python3.11/site-packages/google/cloud/bigquery/__init__.py\", line 35, in <module>\n",
      "    from google.cloud.bigquery.client import Client\n",
      "  File \"/Users/mhd/anaconda3/lib/python3.11/site-packages/google/cloud/bigquery/client.py\", line 69, in <module>\n",
      "    from google.cloud.bigquery import _job_helpers\n",
      "  File \"/Users/mhd/anaconda3/lib/python3.11/site-packages/google/cloud/bigquery/_job_helpers.py\", line 47, in <module>\n",
      "    from google.cloud.bigquery import job\n",
      "  File \"/Users/mhd/anaconda3/lib/python3.11/site-packages/google/cloud/bigquery/job/__init__.py\", line 27, in <module>\n",
      "    from google.cloud.bigquery.job.copy_ import CopyJob\n",
      "  File \"/Users/mhd/anaconda3/lib/python3.11/site-packages/google/cloud/bigquery/job/copy_.py\", line 22, in <module>\n",
      "    from google.cloud.bigquery.table import TableReference\n",
      "  File \"/Users/mhd/anaconda3/lib/python3.11/site-packages/google/cloud/bigquery/table.py\", line 28, in <module>\n",
      "    import pandas  # type: ignore\n",
      "  File \"/Users/mhd/anaconda3/lib/python3.11/site-packages/pandas/__init__.py\", line 49, in <module>\n",
      "    from pandas.core.api import (\n",
      "  File \"/Users/mhd/anaconda3/lib/python3.11/site-packages/pandas/core/api.py\", line 28, in <module>\n",
      "    from pandas.core.arrays import Categorical\n",
      "  File \"/Users/mhd/anaconda3/lib/python3.11/site-packages/pandas/core/arrays/__init__.py\", line 1, in <module>\n",
      "    from pandas.core.arrays.arrow import ArrowExtensionArray\n",
      "  File \"/Users/mhd/anaconda3/lib/python3.11/site-packages/pandas/core/arrays/arrow/__init__.py\", line 5, in <module>\n",
      "    from pandas.core.arrays.arrow.array import ArrowExtensionArray\n",
      "  File \"/Users/mhd/anaconda3/lib/python3.11/site-packages/pandas/core/arrays/arrow/array.py\", line 50, in <module>\n",
      "    from pandas.core import (\n",
      "  File \"/Users/mhd/anaconda3/lib/python3.11/site-packages/pandas/core/ops/__init__.py\", line 8, in <module>\n",
      "    from pandas.core.ops.array_ops import (\n",
      "  File \"/Users/mhd/anaconda3/lib/python3.11/site-packages/pandas/core/ops/array_ops.py\", line 56, in <module>\n",
      "    from pandas.core.computation import expressions\n",
      "  File \"/Users/mhd/anaconda3/lib/python3.11/site-packages/pandas/core/computation/expressions.py\", line 21, in <module>\n",
      "    from pandas.core.computation.check import NUMEXPR_INSTALLED\n",
      "  File \"/Users/mhd/anaconda3/lib/python3.11/site-packages/pandas/core/computation/check.py\", line 5, in <module>\n",
      "    ne = import_optional_dependency(\"numexpr\", errors=\"warn\")\n",
      "  File \"/Users/mhd/anaconda3/lib/python3.11/site-packages/pandas/compat/_optional.py\", line 135, in import_optional_dependency\n",
      "    module = importlib.import_module(name)\n",
      "  File \"/Users/mhd/anaconda3/lib/python3.11/importlib/__init__.py\", line 126, in import_module\n",
      "    return _bootstrap._gcd_import(name[level:], package, level)\n",
      "  File \"/Users/mhd/anaconda3/lib/python3.11/site-packages/numexpr/__init__.py\", line 24, in <module>\n",
      "    from numexpr.interpreter import MAX_THREADS, use_vml, __BLOCK_SIZE1__\n"
     ]
    },
    {
     "ename": "AttributeError",
     "evalue": "_ARRAY_API not found",
     "output_type": "error",
     "traceback": [
      "\u001b[0;31m---------------------------------------------------------------------------\u001b[0m",
      "\u001b[0;31mAttributeError\u001b[0m                            Traceback (most recent call last)",
      "\u001b[0;31mAttributeError\u001b[0m: _ARRAY_API not found"
     ]
    },
    {
     "name": "stderr",
     "output_type": "stream",
     "text": [
      "\n",
      "A module that was compiled using NumPy 1.x cannot be run in\n",
      "NumPy 2.0.1 as it may crash. To support both 1.x and 2.x\n",
      "versions of NumPy, modules must be compiled with NumPy 2.0.\n",
      "Some module may need to rebuild instead e.g. with 'pybind11>=2.12'.\n",
      "\n",
      "If you are a user of the module, the easiest solution will be to\n",
      "downgrade to 'numpy<2' or try to upgrade the affected module.\n",
      "We expect that some modules will need time to support NumPy 2.\n",
      "\n",
      "Traceback (most recent call last):  File \"<frozen runpy>\", line 198, in _run_module_as_main\n",
      "  File \"<frozen runpy>\", line 88, in _run_code\n",
      "  File \"/Users/mhd/anaconda3/lib/python3.11/site-packages/ipykernel_launcher.py\", line 18, in <module>\n",
      "    app.launch_new_instance()\n",
      "  File \"/Users/mhd/anaconda3/lib/python3.11/site-packages/traitlets/config/application.py\", line 1075, in launch_instance\n",
      "    app.start()\n",
      "  File \"/Users/mhd/anaconda3/lib/python3.11/site-packages/ipykernel/kernelapp.py\", line 739, in start\n",
      "    self.io_loop.start()\n",
      "  File \"/Users/mhd/anaconda3/lib/python3.11/site-packages/tornado/platform/asyncio.py\", line 205, in start\n",
      "    self.asyncio_loop.run_forever()\n",
      "  File \"/Users/mhd/anaconda3/lib/python3.11/asyncio/base_events.py\", line 608, in run_forever\n",
      "    self._run_once()\n",
      "  File \"/Users/mhd/anaconda3/lib/python3.11/asyncio/base_events.py\", line 1936, in _run_once\n",
      "    handle._run()\n",
      "  File \"/Users/mhd/anaconda3/lib/python3.11/asyncio/events.py\", line 84, in _run\n",
      "    self._context.run(self._callback, *self._args)\n",
      "  File \"/Users/mhd/anaconda3/lib/python3.11/site-packages/ipykernel/kernelbase.py\", line 545, in dispatch_queue\n",
      "    await self.process_one()\n",
      "  File \"/Users/mhd/anaconda3/lib/python3.11/site-packages/ipykernel/kernelbase.py\", line 534, in process_one\n",
      "    await dispatch(*args)\n",
      "  File \"/Users/mhd/anaconda3/lib/python3.11/site-packages/ipykernel/kernelbase.py\", line 437, in dispatch_shell\n",
      "    await result\n",
      "  File \"/Users/mhd/anaconda3/lib/python3.11/site-packages/ipykernel/ipkernel.py\", line 362, in execute_request\n",
      "    await super().execute_request(stream, ident, parent)\n",
      "  File \"/Users/mhd/anaconda3/lib/python3.11/site-packages/ipykernel/kernelbase.py\", line 778, in execute_request\n",
      "    reply_content = await reply_content\n",
      "  File \"/Users/mhd/anaconda3/lib/python3.11/site-packages/ipykernel/ipkernel.py\", line 449, in do_execute\n",
      "    res = shell.run_cell(\n",
      "  File \"/Users/mhd/anaconda3/lib/python3.11/site-packages/ipykernel/zmqshell.py\", line 549, in run_cell\n",
      "    return super().run_cell(*args, **kwargs)\n",
      "  File \"/Users/mhd/anaconda3/lib/python3.11/site-packages/IPython/core/interactiveshell.py\", line 3048, in run_cell\n",
      "    result = self._run_cell(\n",
      "  File \"/Users/mhd/anaconda3/lib/python3.11/site-packages/IPython/core/interactiveshell.py\", line 3103, in _run_cell\n",
      "    result = runner(coro)\n",
      "  File \"/Users/mhd/anaconda3/lib/python3.11/site-packages/IPython/core/async_helpers.py\", line 129, in _pseudo_sync_runner\n",
      "    coro.send(None)\n",
      "  File \"/Users/mhd/anaconda3/lib/python3.11/site-packages/IPython/core/interactiveshell.py\", line 3308, in run_cell_async\n",
      "    has_raised = await self.run_ast_nodes(code_ast.body, cell_name,\n",
      "  File \"/Users/mhd/anaconda3/lib/python3.11/site-packages/IPython/core/interactiveshell.py\", line 3490, in run_ast_nodes\n",
      "    if await self.run_code(code, result, async_=asy):\n",
      "  File \"/Users/mhd/anaconda3/lib/python3.11/site-packages/IPython/core/interactiveshell.py\", line 3550, in run_code\n",
      "    exec(code_obj, self.user_global_ns, self.user_ns)\n",
      "  File \"/var/folders/s9/5nkmbr990tg499cjlzfn9s600000gn/T/ipykernel_37135/2250472753.py\", line 2, in <module>\n",
      "    from google.cloud import bigquery\n",
      "  File \"/Users/mhd/anaconda3/lib/python3.11/site-packages/google/cloud/bigquery/__init__.py\", line 35, in <module>\n",
      "    from google.cloud.bigquery.client import Client\n",
      "  File \"/Users/mhd/anaconda3/lib/python3.11/site-packages/google/cloud/bigquery/client.py\", line 69, in <module>\n",
      "    from google.cloud.bigquery import _job_helpers\n",
      "  File \"/Users/mhd/anaconda3/lib/python3.11/site-packages/google/cloud/bigquery/_job_helpers.py\", line 47, in <module>\n",
      "    from google.cloud.bigquery import job\n",
      "  File \"/Users/mhd/anaconda3/lib/python3.11/site-packages/google/cloud/bigquery/job/__init__.py\", line 27, in <module>\n",
      "    from google.cloud.bigquery.job.copy_ import CopyJob\n",
      "  File \"/Users/mhd/anaconda3/lib/python3.11/site-packages/google/cloud/bigquery/job/copy_.py\", line 22, in <module>\n",
      "    from google.cloud.bigquery.table import TableReference\n",
      "  File \"/Users/mhd/anaconda3/lib/python3.11/site-packages/google/cloud/bigquery/table.py\", line 28, in <module>\n",
      "    import pandas  # type: ignore\n",
      "  File \"/Users/mhd/anaconda3/lib/python3.11/site-packages/pandas/__init__.py\", line 49, in <module>\n",
      "    from pandas.core.api import (\n",
      "  File \"/Users/mhd/anaconda3/lib/python3.11/site-packages/pandas/core/api.py\", line 28, in <module>\n",
      "    from pandas.core.arrays import Categorical\n",
      "  File \"/Users/mhd/anaconda3/lib/python3.11/site-packages/pandas/core/arrays/__init__.py\", line 1, in <module>\n",
      "    from pandas.core.arrays.arrow import ArrowExtensionArray\n",
      "  File \"/Users/mhd/anaconda3/lib/python3.11/site-packages/pandas/core/arrays/arrow/__init__.py\", line 5, in <module>\n",
      "    from pandas.core.arrays.arrow.array import ArrowExtensionArray\n",
      "  File \"/Users/mhd/anaconda3/lib/python3.11/site-packages/pandas/core/arrays/arrow/array.py\", line 64, in <module>\n",
      "    from pandas.core.arrays.masked import BaseMaskedArray\n",
      "  File \"/Users/mhd/anaconda3/lib/python3.11/site-packages/pandas/core/arrays/masked.py\", line 60, in <module>\n",
      "    from pandas.core import (\n",
      "  File \"/Users/mhd/anaconda3/lib/python3.11/site-packages/pandas/core/nanops.py\", line 52, in <module>\n",
      "    bn = import_optional_dependency(\"bottleneck\", errors=\"warn\")\n",
      "  File \"/Users/mhd/anaconda3/lib/python3.11/site-packages/pandas/compat/_optional.py\", line 135, in import_optional_dependency\n",
      "    module = importlib.import_module(name)\n",
      "  File \"/Users/mhd/anaconda3/lib/python3.11/importlib/__init__.py\", line 126, in import_module\n",
      "    return _bootstrap._gcd_import(name[level:], package, level)\n",
      "  File \"/Users/mhd/anaconda3/lib/python3.11/site-packages/bottleneck/__init__.py\", line 7, in <module>\n",
      "    from .move import (move_argmax, move_argmin, move_max, move_mean, move_median,\n"
     ]
    },
    {
     "ename": "AttributeError",
     "evalue": "_ARRAY_API not found",
     "output_type": "error",
     "traceback": [
      "\u001b[0;31m---------------------------------------------------------------------------\u001b[0m",
      "\u001b[0;31mAttributeError\u001b[0m                            Traceback (most recent call last)",
      "\u001b[0;31mAttributeError\u001b[0m: _ARRAY_API not found"
     ]
    },
    {
     "name": "stderr",
     "output_type": "stream",
     "text": [
      "\n",
      "A module that was compiled using NumPy 1.x cannot be run in\n",
      "NumPy 2.0.1 as it may crash. To support both 1.x and 2.x\n",
      "versions of NumPy, modules must be compiled with NumPy 2.0.\n",
      "Some module may need to rebuild instead e.g. with 'pybind11>=2.12'.\n",
      "\n",
      "If you are a user of the module, the easiest solution will be to\n",
      "downgrade to 'numpy<2' or try to upgrade the affected module.\n",
      "We expect that some modules will need time to support NumPy 2.\n",
      "\n",
      "Traceback (most recent call last):  File \"<frozen runpy>\", line 198, in _run_module_as_main\n",
      "  File \"<frozen runpy>\", line 88, in _run_code\n",
      "  File \"/Users/mhd/anaconda3/lib/python3.11/site-packages/ipykernel_launcher.py\", line 18, in <module>\n",
      "    app.launch_new_instance()\n",
      "  File \"/Users/mhd/anaconda3/lib/python3.11/site-packages/traitlets/config/application.py\", line 1075, in launch_instance\n",
      "    app.start()\n",
      "  File \"/Users/mhd/anaconda3/lib/python3.11/site-packages/ipykernel/kernelapp.py\", line 739, in start\n",
      "    self.io_loop.start()\n",
      "  File \"/Users/mhd/anaconda3/lib/python3.11/site-packages/tornado/platform/asyncio.py\", line 205, in start\n",
      "    self.asyncio_loop.run_forever()\n",
      "  File \"/Users/mhd/anaconda3/lib/python3.11/asyncio/base_events.py\", line 608, in run_forever\n",
      "    self._run_once()\n",
      "  File \"/Users/mhd/anaconda3/lib/python3.11/asyncio/base_events.py\", line 1936, in _run_once\n",
      "    handle._run()\n",
      "  File \"/Users/mhd/anaconda3/lib/python3.11/asyncio/events.py\", line 84, in _run\n",
      "    self._context.run(self._callback, *self._args)\n",
      "  File \"/Users/mhd/anaconda3/lib/python3.11/site-packages/ipykernel/kernelbase.py\", line 545, in dispatch_queue\n",
      "    await self.process_one()\n",
      "  File \"/Users/mhd/anaconda3/lib/python3.11/site-packages/ipykernel/kernelbase.py\", line 534, in process_one\n",
      "    await dispatch(*args)\n",
      "  File \"/Users/mhd/anaconda3/lib/python3.11/site-packages/ipykernel/kernelbase.py\", line 437, in dispatch_shell\n",
      "    await result\n",
      "  File \"/Users/mhd/anaconda3/lib/python3.11/site-packages/ipykernel/ipkernel.py\", line 362, in execute_request\n",
      "    await super().execute_request(stream, ident, parent)\n",
      "  File \"/Users/mhd/anaconda3/lib/python3.11/site-packages/ipykernel/kernelbase.py\", line 778, in execute_request\n",
      "    reply_content = await reply_content\n",
      "  File \"/Users/mhd/anaconda3/lib/python3.11/site-packages/ipykernel/ipkernel.py\", line 449, in do_execute\n",
      "    res = shell.run_cell(\n",
      "  File \"/Users/mhd/anaconda3/lib/python3.11/site-packages/ipykernel/zmqshell.py\", line 549, in run_cell\n",
      "    return super().run_cell(*args, **kwargs)\n",
      "  File \"/Users/mhd/anaconda3/lib/python3.11/site-packages/IPython/core/interactiveshell.py\", line 3048, in run_cell\n",
      "    result = self._run_cell(\n",
      "  File \"/Users/mhd/anaconda3/lib/python3.11/site-packages/IPython/core/interactiveshell.py\", line 3103, in _run_cell\n",
      "    result = runner(coro)\n",
      "  File \"/Users/mhd/anaconda3/lib/python3.11/site-packages/IPython/core/async_helpers.py\", line 129, in _pseudo_sync_runner\n",
      "    coro.send(None)\n",
      "  File \"/Users/mhd/anaconda3/lib/python3.11/site-packages/IPython/core/interactiveshell.py\", line 3308, in run_cell_async\n",
      "    has_raised = await self.run_ast_nodes(code_ast.body, cell_name,\n",
      "  File \"/Users/mhd/anaconda3/lib/python3.11/site-packages/IPython/core/interactiveshell.py\", line 3490, in run_ast_nodes\n",
      "    if await self.run_code(code, result, async_=asy):\n",
      "  File \"/Users/mhd/anaconda3/lib/python3.11/site-packages/IPython/core/interactiveshell.py\", line 3550, in run_code\n",
      "    exec(code_obj, self.user_global_ns, self.user_ns)\n",
      "  File \"/var/folders/s9/5nkmbr990tg499cjlzfn9s600000gn/T/ipykernel_37135/2250472753.py\", line 2, in <module>\n",
      "    from google.cloud import bigquery\n",
      "  File \"/Users/mhd/anaconda3/lib/python3.11/site-packages/google/cloud/bigquery/__init__.py\", line 35, in <module>\n",
      "    from google.cloud.bigquery.client import Client\n",
      "  File \"/Users/mhd/anaconda3/lib/python3.11/site-packages/google/cloud/bigquery/client.py\", line 69, in <module>\n",
      "    from google.cloud.bigquery import _job_helpers\n",
      "  File \"/Users/mhd/anaconda3/lib/python3.11/site-packages/google/cloud/bigquery/_job_helpers.py\", line 47, in <module>\n",
      "    from google.cloud.bigquery import job\n",
      "  File \"/Users/mhd/anaconda3/lib/python3.11/site-packages/google/cloud/bigquery/job/__init__.py\", line 27, in <module>\n",
      "    from google.cloud.bigquery.job.copy_ import CopyJob\n",
      "  File \"/Users/mhd/anaconda3/lib/python3.11/site-packages/google/cloud/bigquery/job/copy_.py\", line 22, in <module>\n",
      "    from google.cloud.bigquery.table import TableReference\n",
      "  File \"/Users/mhd/anaconda3/lib/python3.11/site-packages/google/cloud/bigquery/table.py\", line 33, in <module>\n",
      "    import pyarrow  # type: ignore\n",
      "  File \"/Users/mhd/anaconda3/lib/python3.11/site-packages/pyarrow/__init__.py\", line 65, in <module>\n",
      "    import pyarrow.lib as _lib\n"
     ]
    },
    {
     "ename": "AttributeError",
     "evalue": "_ARRAY_API not found",
     "output_type": "error",
     "traceback": [
      "\u001b[0;31m---------------------------------------------------------------------------\u001b[0m",
      "\u001b[0;31mAttributeError\u001b[0m                            Traceback (most recent call last)",
      "\u001b[0;31mAttributeError\u001b[0m: _ARRAY_API not found"
     ]
    },
    {
     "name": "stderr",
     "output_type": "stream",
     "text": [
      "\n",
      "A module that was compiled using NumPy 1.x cannot be run in\n",
      "NumPy 2.0.1 as it may crash. To support both 1.x and 2.x\n",
      "versions of NumPy, modules must be compiled with NumPy 2.0.\n",
      "Some module may need to rebuild instead e.g. with 'pybind11>=2.12'.\n",
      "\n",
      "If you are a user of the module, the easiest solution will be to\n",
      "downgrade to 'numpy<2' or try to upgrade the affected module.\n",
      "We expect that some modules will need time to support NumPy 2.\n",
      "\n",
      "Traceback (most recent call last):  File \"<frozen runpy>\", line 198, in _run_module_as_main\n",
      "  File \"<frozen runpy>\", line 88, in _run_code\n",
      "  File \"/Users/mhd/anaconda3/lib/python3.11/site-packages/ipykernel_launcher.py\", line 18, in <module>\n",
      "    app.launch_new_instance()\n",
      "  File \"/Users/mhd/anaconda3/lib/python3.11/site-packages/traitlets/config/application.py\", line 1075, in launch_instance\n",
      "    app.start()\n",
      "  File \"/Users/mhd/anaconda3/lib/python3.11/site-packages/ipykernel/kernelapp.py\", line 739, in start\n",
      "    self.io_loop.start()\n",
      "  File \"/Users/mhd/anaconda3/lib/python3.11/site-packages/tornado/platform/asyncio.py\", line 205, in start\n",
      "    self.asyncio_loop.run_forever()\n",
      "  File \"/Users/mhd/anaconda3/lib/python3.11/asyncio/base_events.py\", line 608, in run_forever\n",
      "    self._run_once()\n",
      "  File \"/Users/mhd/anaconda3/lib/python3.11/asyncio/base_events.py\", line 1936, in _run_once\n",
      "    handle._run()\n",
      "  File \"/Users/mhd/anaconda3/lib/python3.11/asyncio/events.py\", line 84, in _run\n",
      "    self._context.run(self._callback, *self._args)\n",
      "  File \"/Users/mhd/anaconda3/lib/python3.11/site-packages/ipykernel/kernelbase.py\", line 545, in dispatch_queue\n",
      "    await self.process_one()\n",
      "  File \"/Users/mhd/anaconda3/lib/python3.11/site-packages/ipykernel/kernelbase.py\", line 534, in process_one\n",
      "    await dispatch(*args)\n",
      "  File \"/Users/mhd/anaconda3/lib/python3.11/site-packages/ipykernel/kernelbase.py\", line 437, in dispatch_shell\n",
      "    await result\n",
      "  File \"/Users/mhd/anaconda3/lib/python3.11/site-packages/ipykernel/ipkernel.py\", line 362, in execute_request\n",
      "    await super().execute_request(stream, ident, parent)\n",
      "  File \"/Users/mhd/anaconda3/lib/python3.11/site-packages/ipykernel/kernelbase.py\", line 778, in execute_request\n",
      "    reply_content = await reply_content\n",
      "  File \"/Users/mhd/anaconda3/lib/python3.11/site-packages/ipykernel/ipkernel.py\", line 449, in do_execute\n",
      "    res = shell.run_cell(\n",
      "  File \"/Users/mhd/anaconda3/lib/python3.11/site-packages/ipykernel/zmqshell.py\", line 549, in run_cell\n",
      "    return super().run_cell(*args, **kwargs)\n",
      "  File \"/Users/mhd/anaconda3/lib/python3.11/site-packages/IPython/core/interactiveshell.py\", line 3048, in run_cell\n",
      "    result = self._run_cell(\n",
      "  File \"/Users/mhd/anaconda3/lib/python3.11/site-packages/IPython/core/interactiveshell.py\", line 3103, in _run_cell\n",
      "    result = runner(coro)\n",
      "  File \"/Users/mhd/anaconda3/lib/python3.11/site-packages/IPython/core/async_helpers.py\", line 129, in _pseudo_sync_runner\n",
      "    coro.send(None)\n",
      "  File \"/Users/mhd/anaconda3/lib/python3.11/site-packages/IPython/core/interactiveshell.py\", line 3308, in run_cell_async\n",
      "    has_raised = await self.run_ast_nodes(code_ast.body, cell_name,\n",
      "  File \"/Users/mhd/anaconda3/lib/python3.11/site-packages/IPython/core/interactiveshell.py\", line 3490, in run_ast_nodes\n",
      "    if await self.run_code(code, result, async_=asy):\n",
      "  File \"/Users/mhd/anaconda3/lib/python3.11/site-packages/IPython/core/interactiveshell.py\", line 3550, in run_code\n",
      "    exec(code_obj, self.user_global_ns, self.user_ns)\n",
      "  File \"/var/folders/s9/5nkmbr990tg499cjlzfn9s600000gn/T/ipykernel_37135/2250472753.py\", line 2, in <module>\n",
      "    from google.cloud import bigquery\n",
      "  File \"/Users/mhd/anaconda3/lib/python3.11/site-packages/google/cloud/bigquery/__init__.py\", line 35, in <module>\n",
      "    from google.cloud.bigquery.client import Client\n",
      "  File \"/Users/mhd/anaconda3/lib/python3.11/site-packages/google/cloud/bigquery/client.py\", line 69, in <module>\n",
      "    from google.cloud.bigquery import _job_helpers\n",
      "  File \"/Users/mhd/anaconda3/lib/python3.11/site-packages/google/cloud/bigquery/_job_helpers.py\", line 47, in <module>\n",
      "    from google.cloud.bigquery import job\n",
      "  File \"/Users/mhd/anaconda3/lib/python3.11/site-packages/google/cloud/bigquery/job/__init__.py\", line 27, in <module>\n",
      "    from google.cloud.bigquery.job.copy_ import CopyJob\n",
      "  File \"/Users/mhd/anaconda3/lib/python3.11/site-packages/google/cloud/bigquery/job/copy_.py\", line 22, in <module>\n",
      "    from google.cloud.bigquery.table import TableReference\n",
      "  File \"/Users/mhd/anaconda3/lib/python3.11/site-packages/google/cloud/bigquery/table.py\", line 62, in <module>\n",
      "    from google.cloud.bigquery import _pandas_helpers\n",
      "  File \"/Users/mhd/anaconda3/lib/python3.11/site-packages/google/cloud/bigquery/_pandas_helpers.py\", line 27, in <module>\n",
      "    from google.cloud.bigquery import _pyarrow_helpers\n",
      "  File \"/Users/mhd/anaconda3/lib/python3.11/site-packages/google/cloud/bigquery/_pyarrow_helpers.py\", line 22, in <module>\n",
      "    import pyarrow  # type: ignore\n",
      "  File \"/Users/mhd/anaconda3/lib/python3.11/site-packages/pyarrow/__init__.py\", line 65, in <module>\n",
      "    import pyarrow.lib as _lib\n"
     ]
    },
    {
     "ename": "AttributeError",
     "evalue": "_ARRAY_API not found",
     "output_type": "error",
     "traceback": [
      "\u001b[0;31m---------------------------------------------------------------------------\u001b[0m",
      "\u001b[0;31mAttributeError\u001b[0m                            Traceback (most recent call last)",
      "\u001b[0;31mAttributeError\u001b[0m: _ARRAY_API not found"
     ]
    },
    {
     "name": "stderr",
     "output_type": "stream",
     "text": [
      "\n",
      "A module that was compiled using NumPy 1.x cannot be run in\n",
      "NumPy 2.0.1 as it may crash. To support both 1.x and 2.x\n",
      "versions of NumPy, modules must be compiled with NumPy 2.0.\n",
      "Some module may need to rebuild instead e.g. with 'pybind11>=2.12'.\n",
      "\n",
      "If you are a user of the module, the easiest solution will be to\n",
      "downgrade to 'numpy<2' or try to upgrade the affected module.\n",
      "We expect that some modules will need time to support NumPy 2.\n",
      "\n",
      "Traceback (most recent call last):  File \"<frozen runpy>\", line 198, in _run_module_as_main\n",
      "  File \"<frozen runpy>\", line 88, in _run_code\n",
      "  File \"/Users/mhd/anaconda3/lib/python3.11/site-packages/ipykernel_launcher.py\", line 18, in <module>\n",
      "    app.launch_new_instance()\n",
      "  File \"/Users/mhd/anaconda3/lib/python3.11/site-packages/traitlets/config/application.py\", line 1075, in launch_instance\n",
      "    app.start()\n",
      "  File \"/Users/mhd/anaconda3/lib/python3.11/site-packages/ipykernel/kernelapp.py\", line 739, in start\n",
      "    self.io_loop.start()\n",
      "  File \"/Users/mhd/anaconda3/lib/python3.11/site-packages/tornado/platform/asyncio.py\", line 205, in start\n",
      "    self.asyncio_loop.run_forever()\n",
      "  File \"/Users/mhd/anaconda3/lib/python3.11/asyncio/base_events.py\", line 608, in run_forever\n",
      "    self._run_once()\n",
      "  File \"/Users/mhd/anaconda3/lib/python3.11/asyncio/base_events.py\", line 1936, in _run_once\n",
      "    handle._run()\n",
      "  File \"/Users/mhd/anaconda3/lib/python3.11/asyncio/events.py\", line 84, in _run\n",
      "    self._context.run(self._callback, *self._args)\n",
      "  File \"/Users/mhd/anaconda3/lib/python3.11/site-packages/ipykernel/kernelbase.py\", line 545, in dispatch_queue\n",
      "    await self.process_one()\n",
      "  File \"/Users/mhd/anaconda3/lib/python3.11/site-packages/ipykernel/kernelbase.py\", line 534, in process_one\n",
      "    await dispatch(*args)\n",
      "  File \"/Users/mhd/anaconda3/lib/python3.11/site-packages/ipykernel/kernelbase.py\", line 437, in dispatch_shell\n",
      "    await result\n",
      "  File \"/Users/mhd/anaconda3/lib/python3.11/site-packages/ipykernel/ipkernel.py\", line 362, in execute_request\n",
      "    await super().execute_request(stream, ident, parent)\n",
      "  File \"/Users/mhd/anaconda3/lib/python3.11/site-packages/ipykernel/kernelbase.py\", line 778, in execute_request\n",
      "    reply_content = await reply_content\n",
      "  File \"/Users/mhd/anaconda3/lib/python3.11/site-packages/ipykernel/ipkernel.py\", line 449, in do_execute\n",
      "    res = shell.run_cell(\n",
      "  File \"/Users/mhd/anaconda3/lib/python3.11/site-packages/ipykernel/zmqshell.py\", line 549, in run_cell\n",
      "    return super().run_cell(*args, **kwargs)\n",
      "  File \"/Users/mhd/anaconda3/lib/python3.11/site-packages/IPython/core/interactiveshell.py\", line 3048, in run_cell\n",
      "    result = self._run_cell(\n",
      "  File \"/Users/mhd/anaconda3/lib/python3.11/site-packages/IPython/core/interactiveshell.py\", line 3103, in _run_cell\n",
      "    result = runner(coro)\n",
      "  File \"/Users/mhd/anaconda3/lib/python3.11/site-packages/IPython/core/async_helpers.py\", line 129, in _pseudo_sync_runner\n",
      "    coro.send(None)\n",
      "  File \"/Users/mhd/anaconda3/lib/python3.11/site-packages/IPython/core/interactiveshell.py\", line 3308, in run_cell_async\n",
      "    has_raised = await self.run_ast_nodes(code_ast.body, cell_name,\n",
      "  File \"/Users/mhd/anaconda3/lib/python3.11/site-packages/IPython/core/interactiveshell.py\", line 3490, in run_ast_nodes\n",
      "    if await self.run_code(code, result, async_=asy):\n",
      "  File \"/Users/mhd/anaconda3/lib/python3.11/site-packages/IPython/core/interactiveshell.py\", line 3550, in run_code\n",
      "    exec(code_obj, self.user_global_ns, self.user_ns)\n",
      "  File \"/var/folders/s9/5nkmbr990tg499cjlzfn9s600000gn/T/ipykernel_37135/2250472753.py\", line 2, in <module>\n",
      "    from google.cloud import bigquery\n",
      "  File \"/Users/mhd/anaconda3/lib/python3.11/site-packages/google/cloud/bigquery/__init__.py\", line 35, in <module>\n",
      "    from google.cloud.bigquery.client import Client\n",
      "  File \"/Users/mhd/anaconda3/lib/python3.11/site-packages/google/cloud/bigquery/client.py\", line 69, in <module>\n",
      "    from google.cloud.bigquery import _job_helpers\n",
      "  File \"/Users/mhd/anaconda3/lib/python3.11/site-packages/google/cloud/bigquery/_job_helpers.py\", line 47, in <module>\n",
      "    from google.cloud.bigquery import job\n",
      "  File \"/Users/mhd/anaconda3/lib/python3.11/site-packages/google/cloud/bigquery/job/__init__.py\", line 27, in <module>\n",
      "    from google.cloud.bigquery.job.copy_ import CopyJob\n",
      "  File \"/Users/mhd/anaconda3/lib/python3.11/site-packages/google/cloud/bigquery/job/copy_.py\", line 22, in <module>\n",
      "    from google.cloud.bigquery.table import TableReference\n",
      "  File \"/Users/mhd/anaconda3/lib/python3.11/site-packages/google/cloud/bigquery/table.py\", line 62, in <module>\n",
      "    from google.cloud.bigquery import _pandas_helpers\n",
      "  File \"/Users/mhd/anaconda3/lib/python3.11/site-packages/google/cloud/bigquery/_pandas_helpers.py\", line 28, in <module>\n",
      "    from google.cloud.bigquery import _versions_helpers\n",
      "  File \"/Users/mhd/anaconda3/lib/python3.11/site-packages/google/cloud/bigquery/_versions_helpers.py\", line 248, in <module>\n",
      "    and PYARROW_VERSIONS.try_import() is not None\n",
      "  File \"/Users/mhd/anaconda3/lib/python3.11/site-packages/google/cloud/bigquery/_versions_helpers.py\", line 78, in try_import\n",
      "    import pyarrow\n",
      "  File \"/Users/mhd/anaconda3/lib/python3.11/site-packages/pyarrow/__init__.py\", line 65, in <module>\n",
      "    import pyarrow.lib as _lib\n"
     ]
    },
    {
     "ename": "AttributeError",
     "evalue": "_ARRAY_API not found",
     "output_type": "error",
     "traceback": [
      "\u001b[0;31m---------------------------------------------------------------------------\u001b[0m",
      "\u001b[0;31mAttributeError\u001b[0m                            Traceback (most recent call last)",
      "\u001b[0;31mAttributeError\u001b[0m: _ARRAY_API not found"
     ]
    },
    {
     "name": "stderr",
     "output_type": "stream",
     "text": [
      "\n",
      "A module that was compiled using NumPy 1.x cannot be run in\n",
      "NumPy 2.0.1 as it may crash. To support both 1.x and 2.x\n",
      "versions of NumPy, modules must be compiled with NumPy 2.0.\n",
      "Some module may need to rebuild instead e.g. with 'pybind11>=2.12'.\n",
      "\n",
      "If you are a user of the module, the easiest solution will be to\n",
      "downgrade to 'numpy<2' or try to upgrade the affected module.\n",
      "We expect that some modules will need time to support NumPy 2.\n",
      "\n",
      "Traceback (most recent call last):  File \"<frozen runpy>\", line 198, in _run_module_as_main\n",
      "  File \"<frozen runpy>\", line 88, in _run_code\n",
      "  File \"/Users/mhd/anaconda3/lib/python3.11/site-packages/ipykernel_launcher.py\", line 18, in <module>\n",
      "    app.launch_new_instance()\n",
      "  File \"/Users/mhd/anaconda3/lib/python3.11/site-packages/traitlets/config/application.py\", line 1075, in launch_instance\n",
      "    app.start()\n",
      "  File \"/Users/mhd/anaconda3/lib/python3.11/site-packages/ipykernel/kernelapp.py\", line 739, in start\n",
      "    self.io_loop.start()\n",
      "  File \"/Users/mhd/anaconda3/lib/python3.11/site-packages/tornado/platform/asyncio.py\", line 205, in start\n",
      "    self.asyncio_loop.run_forever()\n",
      "  File \"/Users/mhd/anaconda3/lib/python3.11/asyncio/base_events.py\", line 608, in run_forever\n",
      "    self._run_once()\n",
      "  File \"/Users/mhd/anaconda3/lib/python3.11/asyncio/base_events.py\", line 1936, in _run_once\n",
      "    handle._run()\n",
      "  File \"/Users/mhd/anaconda3/lib/python3.11/asyncio/events.py\", line 84, in _run\n",
      "    self._context.run(self._callback, *self._args)\n",
      "  File \"/Users/mhd/anaconda3/lib/python3.11/site-packages/ipykernel/kernelbase.py\", line 545, in dispatch_queue\n",
      "    await self.process_one()\n",
      "  File \"/Users/mhd/anaconda3/lib/python3.11/site-packages/ipykernel/kernelbase.py\", line 534, in process_one\n",
      "    await dispatch(*args)\n",
      "  File \"/Users/mhd/anaconda3/lib/python3.11/site-packages/ipykernel/kernelbase.py\", line 437, in dispatch_shell\n",
      "    await result\n",
      "  File \"/Users/mhd/anaconda3/lib/python3.11/site-packages/ipykernel/ipkernel.py\", line 362, in execute_request\n",
      "    await super().execute_request(stream, ident, parent)\n",
      "  File \"/Users/mhd/anaconda3/lib/python3.11/site-packages/ipykernel/kernelbase.py\", line 778, in execute_request\n",
      "    reply_content = await reply_content\n",
      "  File \"/Users/mhd/anaconda3/lib/python3.11/site-packages/ipykernel/ipkernel.py\", line 449, in do_execute\n",
      "    res = shell.run_cell(\n",
      "  File \"/Users/mhd/anaconda3/lib/python3.11/site-packages/ipykernel/zmqshell.py\", line 549, in run_cell\n",
      "    return super().run_cell(*args, **kwargs)\n",
      "  File \"/Users/mhd/anaconda3/lib/python3.11/site-packages/IPython/core/interactiveshell.py\", line 3048, in run_cell\n",
      "    result = self._run_cell(\n",
      "  File \"/Users/mhd/anaconda3/lib/python3.11/site-packages/IPython/core/interactiveshell.py\", line 3103, in _run_cell\n",
      "    result = runner(coro)\n",
      "  File \"/Users/mhd/anaconda3/lib/python3.11/site-packages/IPython/core/async_helpers.py\", line 129, in _pseudo_sync_runner\n",
      "    coro.send(None)\n",
      "  File \"/Users/mhd/anaconda3/lib/python3.11/site-packages/IPython/core/interactiveshell.py\", line 3308, in run_cell_async\n",
      "    has_raised = await self.run_ast_nodes(code_ast.body, cell_name,\n",
      "  File \"/Users/mhd/anaconda3/lib/python3.11/site-packages/IPython/core/interactiveshell.py\", line 3490, in run_ast_nodes\n",
      "    if await self.run_code(code, result, async_=asy):\n",
      "  File \"/Users/mhd/anaconda3/lib/python3.11/site-packages/IPython/core/interactiveshell.py\", line 3550, in run_code\n",
      "    exec(code_obj, self.user_global_ns, self.user_ns)\n",
      "  File \"/var/folders/s9/5nkmbr990tg499cjlzfn9s600000gn/T/ipykernel_37135/2250472753.py\", line 2, in <module>\n",
      "    from google.cloud import bigquery\n",
      "  File \"/Users/mhd/anaconda3/lib/python3.11/site-packages/google/cloud/bigquery/__init__.py\", line 35, in <module>\n",
      "    from google.cloud.bigquery.client import Client\n",
      "  File \"/Users/mhd/anaconda3/lib/python3.11/site-packages/google/cloud/bigquery/client.py\", line 69, in <module>\n",
      "    from google.cloud.bigquery import _job_helpers\n",
      "  File \"/Users/mhd/anaconda3/lib/python3.11/site-packages/google/cloud/bigquery/_job_helpers.py\", line 47, in <module>\n",
      "    from google.cloud.bigquery import job\n",
      "  File \"/Users/mhd/anaconda3/lib/python3.11/site-packages/google/cloud/bigquery/job/__init__.py\", line 27, in <module>\n",
      "    from google.cloud.bigquery.job.copy_ import CopyJob\n",
      "  File \"/Users/mhd/anaconda3/lib/python3.11/site-packages/google/cloud/bigquery/job/copy_.py\", line 22, in <module>\n",
      "    from google.cloud.bigquery.table import TableReference\n",
      "  File \"/Users/mhd/anaconda3/lib/python3.11/site-packages/google/cloud/bigquery/table.py\", line 62, in <module>\n",
      "    from google.cloud.bigquery import _pandas_helpers\n",
      "  File \"/Users/mhd/anaconda3/lib/python3.11/site-packages/google/cloud/bigquery/_pandas_helpers.py\", line 52, in <module>\n",
      "    pyarrow = _versions_helpers.PYARROW_VERSIONS.try_import()\n",
      "  File \"/Users/mhd/anaconda3/lib/python3.11/site-packages/google/cloud/bigquery/_versions_helpers.py\", line 78, in try_import\n",
      "    import pyarrow\n",
      "  File \"/Users/mhd/anaconda3/lib/python3.11/site-packages/pyarrow/__init__.py\", line 65, in <module>\n",
      "    import pyarrow.lib as _lib\n"
     ]
    },
    {
     "ename": "AttributeError",
     "evalue": "_ARRAY_API not found",
     "output_type": "error",
     "traceback": [
      "\u001b[0;31m---------------------------------------------------------------------------\u001b[0m",
      "\u001b[0;31mAttributeError\u001b[0m                            Traceback (most recent call last)",
      "\u001b[0;31mAttributeError\u001b[0m: _ARRAY_API not found"
     ]
    },
    {
     "name": "stderr",
     "output_type": "stream",
     "text": [
      "\n",
      "A module that was compiled using NumPy 1.x cannot be run in\n",
      "NumPy 2.0.1 as it may crash. To support both 1.x and 2.x\n",
      "versions of NumPy, modules must be compiled with NumPy 2.0.\n",
      "Some module may need to rebuild instead e.g. with 'pybind11>=2.12'.\n",
      "\n",
      "If you are a user of the module, the easiest solution will be to\n",
      "downgrade to 'numpy<2' or try to upgrade the affected module.\n",
      "We expect that some modules will need time to support NumPy 2.\n",
      "\n",
      "Traceback (most recent call last):  File \"<frozen runpy>\", line 198, in _run_module_as_main\n",
      "  File \"<frozen runpy>\", line 88, in _run_code\n",
      "  File \"/Users/mhd/anaconda3/lib/python3.11/site-packages/ipykernel_launcher.py\", line 18, in <module>\n",
      "    app.launch_new_instance()\n",
      "  File \"/Users/mhd/anaconda3/lib/python3.11/site-packages/traitlets/config/application.py\", line 1075, in launch_instance\n",
      "    app.start()\n",
      "  File \"/Users/mhd/anaconda3/lib/python3.11/site-packages/ipykernel/kernelapp.py\", line 739, in start\n",
      "    self.io_loop.start()\n",
      "  File \"/Users/mhd/anaconda3/lib/python3.11/site-packages/tornado/platform/asyncio.py\", line 205, in start\n",
      "    self.asyncio_loop.run_forever()\n",
      "  File \"/Users/mhd/anaconda3/lib/python3.11/asyncio/base_events.py\", line 608, in run_forever\n",
      "    self._run_once()\n",
      "  File \"/Users/mhd/anaconda3/lib/python3.11/asyncio/base_events.py\", line 1936, in _run_once\n",
      "    handle._run()\n",
      "  File \"/Users/mhd/anaconda3/lib/python3.11/asyncio/events.py\", line 84, in _run\n",
      "    self._context.run(self._callback, *self._args)\n",
      "  File \"/Users/mhd/anaconda3/lib/python3.11/site-packages/ipykernel/kernelbase.py\", line 545, in dispatch_queue\n",
      "    await self.process_one()\n",
      "  File \"/Users/mhd/anaconda3/lib/python3.11/site-packages/ipykernel/kernelbase.py\", line 534, in process_one\n",
      "    await dispatch(*args)\n",
      "  File \"/Users/mhd/anaconda3/lib/python3.11/site-packages/ipykernel/kernelbase.py\", line 437, in dispatch_shell\n",
      "    await result\n",
      "  File \"/Users/mhd/anaconda3/lib/python3.11/site-packages/ipykernel/ipkernel.py\", line 362, in execute_request\n",
      "    await super().execute_request(stream, ident, parent)\n",
      "  File \"/Users/mhd/anaconda3/lib/python3.11/site-packages/ipykernel/kernelbase.py\", line 778, in execute_request\n",
      "    reply_content = await reply_content\n",
      "  File \"/Users/mhd/anaconda3/lib/python3.11/site-packages/ipykernel/ipkernel.py\", line 449, in do_execute\n",
      "    res = shell.run_cell(\n",
      "  File \"/Users/mhd/anaconda3/lib/python3.11/site-packages/ipykernel/zmqshell.py\", line 549, in run_cell\n",
      "    return super().run_cell(*args, **kwargs)\n",
      "  File \"/Users/mhd/anaconda3/lib/python3.11/site-packages/IPython/core/interactiveshell.py\", line 3048, in run_cell\n",
      "    result = self._run_cell(\n",
      "  File \"/Users/mhd/anaconda3/lib/python3.11/site-packages/IPython/core/interactiveshell.py\", line 3103, in _run_cell\n",
      "    result = runner(coro)\n",
      "  File \"/Users/mhd/anaconda3/lib/python3.11/site-packages/IPython/core/async_helpers.py\", line 129, in _pseudo_sync_runner\n",
      "    coro.send(None)\n",
      "  File \"/Users/mhd/anaconda3/lib/python3.11/site-packages/IPython/core/interactiveshell.py\", line 3308, in run_cell_async\n",
      "    has_raised = await self.run_ast_nodes(code_ast.body, cell_name,\n",
      "  File \"/Users/mhd/anaconda3/lib/python3.11/site-packages/IPython/core/interactiveshell.py\", line 3490, in run_ast_nodes\n",
      "    if await self.run_code(code, result, async_=asy):\n",
      "  File \"/Users/mhd/anaconda3/lib/python3.11/site-packages/IPython/core/interactiveshell.py\", line 3550, in run_code\n",
      "    exec(code_obj, self.user_global_ns, self.user_ns)\n",
      "  File \"/var/folders/s9/5nkmbr990tg499cjlzfn9s600000gn/T/ipykernel_37135/2250472753.py\", line 2, in <module>\n",
      "    from google.cloud import bigquery\n",
      "  File \"/Users/mhd/anaconda3/lib/python3.11/site-packages/google/cloud/bigquery/__init__.py\", line 35, in <module>\n",
      "    from google.cloud.bigquery.client import Client\n",
      "  File \"/Users/mhd/anaconda3/lib/python3.11/site-packages/google/cloud/bigquery/client.py\", line 124, in <module>\n",
      "    pyarrow = _versions_helpers.PYARROW_VERSIONS.try_import()\n",
      "  File \"/Users/mhd/anaconda3/lib/python3.11/site-packages/google/cloud/bigquery/_versions_helpers.py\", line 78, in try_import\n",
      "    import pyarrow\n",
      "  File \"/Users/mhd/anaconda3/lib/python3.11/site-packages/pyarrow/__init__.py\", line 65, in <module>\n",
      "    import pyarrow.lib as _lib\n"
     ]
    },
    {
     "ename": "AttributeError",
     "evalue": "_ARRAY_API not found",
     "output_type": "error",
     "traceback": [
      "\u001b[0;31m---------------------------------------------------------------------------\u001b[0m",
      "\u001b[0;31mAttributeError\u001b[0m                            Traceback (most recent call last)",
      "\u001b[0;31mAttributeError\u001b[0m: _ARRAY_API not found"
     ]
    },
    {
     "name": "stdout",
     "output_type": "stream",
     "text": [
      "[SchemaField('weather', 'STRING', 'NULLABLE', None, None, (), None), SchemaField('name', 'STRING', 'NULLABLE', None, None, (), None), SchemaField('visibility', 'INT64', 'NULLABLE', None, None, (), None), SchemaField('wind', 'FLOAT64', 'NULLABLE', None, None, (), None), SchemaField('clouds', 'STRING', 'NULLABLE', None, None, (), None), SchemaField('datetime', 'INT64', 'NULLABLE', None, None, (), None), SchemaField('date', 'TIMESTAMP', 'NULLABLE', None, None, (), None), SchemaField('id', 'INT64', 'NULLABLE', None, None, (), None), SchemaField('cod', 'INT64', 'NULLABLE', None, None, (), None), SchemaField('isRaining', 'INT64', 'NULLABLE', None, None, (), None)]\n"
     ]
    }
   ],
   "source": [
    "from datetime import datetime\n",
    "from google.cloud import bigquery\n",
    "from typing import Any, Dict, List\n",
    "import json\n",
    "\n",
    " \n",
    "json_data = {\n",
    "    \"weather\": \"humid\",\n",
    "    \"name\": \"Alberta\",\n",
    "    \"visibility\": 10000,\n",
    "    \"wind\": 5.5,\n",
    "    \"clouds\": \"Overcast\",\n",
    "    \"datetime\": 1485789600,\n",
    "    \"date\": \"2024-08-28\",\n",
    "    \"id\": 2643743,\n",
    "    \"name\": \"London\",\n",
    "    \"cod\": 200,\n",
    "    \"isRaining\": True\n",
    "}\n",
    "\n",
    "def get_bq_type(value:any):\n",
    "        if isinstance(value, int):\n",
    "            return \"INT64\"\n",
    "        elif isinstance(value, float):\n",
    "            return \"FLOAT64\"\n",
    "        elif isinstance(value, bool):\n",
    "            return \"BOOL\"\n",
    "        elif isinstance(value, str):\n",
    "            try:\n",
    "                from datetime import datetime\n",
    "                datetime.strptime(value, \"%Y-%m-%d\")\n",
    "                return \"TIMESTAMP\"\n",
    "            except ValueError:\n",
    "                pass\n",
    "            return \"STRING\"\n",
    "        elif isinstance(value, int) and 0 <= value <= datetime.now().timestamp():\n",
    "            try:\n",
    "                datetime.fromtimestamp(value)\n",
    "                return True\n",
    "            except ValueError:\n",
    "                return False                \n",
    "        else:\n",
    "            return \"STRING\"\n",
    " \n",
    "def convert_json_to_bq_schema(json_data: Dict[str, Any]) -> List[bigquery.SchemaField]:\n",
    "    \"\"\"Converts JSON data to a list of SchemaField objects for BigQuery.\"\"\"\n",
    "    bq_schema = []\n",
    "    for key, value in json_data.items():\n",
    "        bq_schema.append(bigquery.SchemaField(name=key, field_type=get_bq_type(value), mode=\"NULLABLE\"))\n",
    "    return bq_schema\n",
    " \n",
    "### Test here: ###\n",
    "schema = convert_json_to_bq_schema(json_data)\n",
    "print(schema)"
   ]
  }
 ],
 "metadata": {
  "kernelspec": {
   "display_name": "base",
   "language": "python",
   "name": "python3"
  },
  "language_info": {
   "codemirror_mode": {
    "name": "ipython",
    "version": 3
   },
   "file_extension": ".py",
   "mimetype": "text/x-python",
   "name": "python",
   "nbconvert_exporter": "python",
   "pygments_lexer": "ipython3",
   "version": "3.11.9"
  }
 },
 "nbformat": 4,
 "nbformat_minor": 2
}
